Workbook

Sheet per_question
A1: run_id | B1: run_ts | C1: xls_input | D1: q_index | E1: has_items | F1: no_result_claim | G1: api_note | H1: items_count | I1: avg_pca | J1: precision | K1: recall | L1: f1 | M1: cpr_all | N1: constraints_total | O1: constraints_correct | P1: no_result_score | Q1: cm_label | R1: cm_gt | S1: cm_pred | T1: cm_threshold | U1: answer_excerpt | V1: gold_json
A2: 20251113-083353 | B2: 2025-11-13T08:33:53 | C2: test/test_vector_rval1.xlsx | D2: 1 | E2: TRUE | F2: FALSE | H2: =COUNTIF(per_item!$D$2:$D$108,per_question!D2) -> 5 | I2: =IF(H2=0,"",SUMIF(per_item!$D$2:$D$108,per_question!D2,per_item!$I$2:$I$108)/per_question!H2) -> 1 | J2: 1 | K2: 1 | L2: 1 | M2: =IF(H2=0,"",SUMIF(per_item!$D$2:$D$108,per_question!D2,per_item!$J$2:$J$108)/per_question!H2) -> 1 | N2: 15 | O2: 15 | P2: =IF(AND(F2=TRUE,G2="API has data"),0,IF(AND(F2=TRUE,G2="API empty"),1,"")) | Q2: =IF(AND(R2="Pos",S2="Pos"),"TP",IF(AND(R2="Neg",S2="Neg",P2=1),"TN",IF(AND(R2="Pos",S2="Neg"),"FN",IF(AND(R2="Neg",S2="Neg",P2=""),"FP","UNK")))) -> TP | R2: Pos | S2: =IF(AND(M2>=global_runs!$D$2,per_question!F2=FALSE),"Pos",IF(AND(M2<global_runs!$D$2,per_question!F2=FALSE),"Neg",IF(per_question!F2=TRUE,"Neg","Unknown"))) -> Pos | T2: 0.6 | U2: Berikut adalah beberapa pilihan rumah yang dijual di daerah Cemara: 1. **Dijual Rumah di Jl. Cemara, Kota Medan** - Harga: 695.000.000 - Spesifikasi: LT 76 m², LB 120 m², 2.5 lantai - Catatan: Perlu r | V2: {"keyword": "cemara", "tipe_listing": 1, "jenis_properti": 1, "page": 1}
A3: 20251113-083353 | B3: 2025-11-13T08:33:53 | C3: test/test_vector_rval1.xlsx | D3: 2 | E3: TRUE | F3: FALSE | H3: =COUNTIF(per_item!$D$2:$D$108,per_question!D3) -> 5 | I3: =IF(H3=0,"",SUMIF(per_item!$D$2:$D$108,per_question!D3,per_item!$I$2:$I$108)/per_question!H3) -> 1 | J3: 1 | K3: 1 | L3: 1 | M3: =IF(H3=0,"",SUMIF(per_item!$D$2:$D$108,per_question!D3,per_item!$J$2:$J$108)/per_question!H3) -> 1 | N3: 15 | O3: 15 | P3: =IF(AND(F3=TRUE,G3="API has data"),0,IF(AND(F3=TRUE,G3="API empty"),1,"")) | Q3: =IF(AND(R3="Pos",S3="Pos"),"TP",IF(AND(R3="Neg",S3="Neg",P3=1),"TN",IF(AND(R3="Pos",S3="Neg"),"FN",IF(AND(R3="Neg",S3="Neg",P3=""),"FP","UNK")))) -> TP | R3: Pos | S3: =IF(AND(M3>=global_runs!$D$2,per_question!F3=FALSE),"Pos",IF(AND(M3<global_runs!$D$2,per_question!F3=FALSE),"Neg",IF(per_question!F3=TRUE,"Neg","Unknown"))) -> Pos | T3: 0.6 | U3: Berikut adalah beberapa pilihan rumah yang dijual di daerah Ringroad: 1. **Dijual full perabot daerah Ringroad** - Lokasi: Jl. Ps. II, komp. De Zurich, Kel. Tanjung Sari, Kec. Medan Selayang - Harga: | V3: {"keyword": "ringroad", "tipe_listing": 1, "jenis_properti": 1, "page": 1}
A4: 20251113-083353 | B4: 2025-11-13T08:33:53 | C4: test/test_vector_rval1.xlsx | D4: 3 | E4: TRUE | F4: FALSE | H4: =COUNTIF(per_item!$D$2:$D$108,per_question!D4) -> 2 | I4: =IF(H4=0,"",SUMIF(per_item!$D$2:$D$108,per_question!D4,per_item!$I$2:$I$108)/per_question!H4) -> 1 | J4: 1 | K4: 1 | L4: 1 | M4: =IF(H4=0,"",SUMIF(per_item!$D$2:$D$108,per_question!D4,per_item!$J$2:$J$108)/per_question!H4) -> 1 | N4: 6 | O4: 6 | P4: =IF(AND(F4=TRUE,G4="API has data"),0,IF(AND(F4=TRUE,G4="API empty"),1,"")) | Q4: =IF(AND(R4="Pos",S4="Pos"),"TP",IF(AND(R4="Neg",S4="Neg",P4=1),"TN",IF(AND(R4="Pos",S4="Neg"),"FN",IF(AND(R4="Neg",S4="Neg",P4=""),"FP","UNK")))) -> TP | R4: Pos | S4: =IF(AND(M4>=global_runs!$D$2,per_question!F4=FALSE),"Pos",IF(AND(M4<global_runs!$D$2,per_question!F4=FALSE),"Neg",IF(per_question!F4=TRUE,"Neg","Unknown"))) -> Pos | T4: 0.6 | U4: Berikut adalah pilihan rumah sewa di Medan yang dapat Anda pertimbangkan: 1. **Disewakan Rumah di Royal Sumatera** - Lokasi: Jln. Jamin Ginting, Komp. komplek royal sumatera, Kel. Mangga, Kec. Medan T | V4: {"keyword": "medan", "tipe_listing": 2, "jenis_properti": 1, "page": 1}
A5: 20251113-083353 | B5: 2025-11-13T08:33:53 | C5: test/test_vector_rval1.xlsx | D5: 4 | E5: TRUE | F5: FALSE | H5: =COUNTIF(per_item!$D$2:$D$108,per_question!D5) -> 3 | I5: =IF(H5=0,"",SUMIF(per_item!$D$2:$D$108,per_question!D5,per_item!$I$2:$I$108)/per_question!H5) -> 0.93333333 | J5: 1 | K5: 0.93333333 | L5: 0.96551724 | M5: =IF(H5=0,"",SUMIF(per_item!$D$2:$D$108,per_question!D5,per_item!$J$2:$J$108)/per_question!H5) -> 0.66666667 | N5: 15 | O5: 14 | P5: =IF(AND(F5=TRUE,G5="API has data"),0,IF(AND(F5=TRUE,G5="API empty"),1,"")) | Q5: =IF(AND(R5="Pos",S5="Pos"),"TP",IF(AND(R5="Neg",S5="Neg",P5=1),"TN",IF(AND(R5="Pos",S5="Neg"),"FN",IF(AND(R5="Neg",S5="Neg",P5=""),"FP","UNK")))) -> TP | R5: Pos | S5: =IF(AND(M5>=global_runs!$D$2,per_question!F5=FALSE),"Pos",IF(AND(M5<global_runs!$D$2,per_question!F5=FALSE),"Neg",IF(per_question!F5=TRUE,"Neg","Unknown"))) -> Pos | T5: 0.6 | U5: Berikut adalah beberapa pilihan rumah yang dijual di daerah Cemara dengan harga sekitar 1M: 1. **Dijual Rumah daerah Cemara** - Lokasi: Jl. Cemara, gg gg. seri, Kel. P Berayan Darat II, Kec. Medan Tim | V5: {"keyword": "cemara", "harga_min": 800000000, "harga_max": 1200000000, "tipe_listing": 1, "jenis_properti": 1, "page": 1}
A6: 20251113-083353 | B6: 2025-11-13T08:33:53 | C6: test/test_vector_rval1.xlsx | D6: 5 | E6: FALSE | F6: TRUE | G6: API has data | H6: =COUNTIF(per_item!$D$2:$D$108,per_question!D6) -> 0 | I6: =IF(H6=0,"",SUMIF(per_item!$D$2:$D$108,per_question!D6,per_item!$I$2:$I$108)/per_question!H6) | M6: =IF(H6=0,"",SUMIF(per_item!$D$2:$D$108,per_question!D6,per_item!$J$2:$J$108)/per_question!H6) | N6: 0 | O6: 0 | P6: =IF(AND(F6=TRUE,G6="API has data"),0,IF(AND(F6=TRUE,G6="API empty"),1,"")) -> 0 | Q6: =IF(AND(R6="Pos",S6="Pos"),"TP",IF(AND(R6="Neg",S6="Neg",P6=1),"TN",IF(AND(R6="Pos",S6="Neg"),"FN",IF(AND(R6="Neg",S6="Neg",P6=""),"FP","UNK")))) -> FN | R6: Pos | S6: =IF(AND(M6>=global_runs!$D$2,per_question!F6=FALSE),"Pos",IF(AND(M6<global_runs!$D$2,per_question!F6=FALSE),"Neg",IF(per_question!F6=TRUE,"Neg","Unknown"))) -> Neg | T6: 0.6 | U6: Maaf, saya tidak menemukan rumah dijual di daerah Ringroad dengan harga di bawah 800 juta dan memiliki 3 kamar. Apakah ada kata kunci lain yang ingin Anda cari atau mungkin Anda ingin mengubah kriteri | V6: {"keyword": "ringroad", "harga_max": 800000000, "kamar_tidur": 3, "tipe_listing": 1, "jenis_properti": 1, "page": 1}
A7: 20251113-083353 | B7: 2025-11-13T08:33:53 | C7: test/test_vector_rval1.xlsx | D7: 6 | E7: FALSE | F7: TRUE | G7: API has data | H7: =COUNTIF(per_item!$D$2:$D$108,per_question!D7) -> 0 | I7: =IF(H7=0,"",SUMIF(per_item!$D$2:$D$108,per_question!D7,per_item!$I$2:$I$108)/per_question!H7) | M7: =IF(H7=0,"",SUMIF(per_item!$D$2:$D$108,per_question!D7,per_item!$J$2:$J$108)/per_question!H7) | N7: 0 | O7: 0 | P7: =IF(AND(F7=TRUE,G7="API has data"),0,IF(AND(F7=TRUE,G7="API empty"),1,"")) -> 0 | Q7: =IF(AND(R7="Pos",S7="Pos"),"TP",IF(AND(R7="Neg",S7="Neg",P7=1),"TN",IF(AND(R7="Pos",S7="Neg"),"FN",IF(AND(R7="Neg",S7="Neg",P7=""),"FP","UNK")))) -> FN | R7: Pos | S7: =IF(AND(M7>=global_runs!$D$2,per_question!F7=FALSE),"Pos",IF(AND(M7<global_runs!$D$2,per_question!F7=FALSE),"Neg",IF(per_question!F7=TRUE,"Neg","Unknown"))) -> Neg | T7: 0.6 | U7: Maaf, tidak ada rumah sewa di Medan dengan harga di bawah 50 juta dan memiliki 3 kamar. Berikut adalah beberapa properti yang mungkin menarik untuk Anda, meskipun tidak sesuai dengan kriteria harga: 1 | V7: {"keyword": "medan", "harga_max": 50000000, "kamar_tidur": 3, "tipe_listing": 2, "jenis_properti": 1, "page": 1, "paginate": 5}
A8: 20251113-083353 | B8: 2025-11-13T08:33:53 | C8: test/test_vector_rval1.xlsx | D8: 7 | E8: FALSE | F8: TRUE | G8: API empty | H8: =COUNTIF(per_item!$D$2:$D$108,per_question!D8) -> 0 | I8: =IF(H8=0,"",SUMIF(per_item!$D$2:$D$108,per_question!D8,per_item!$I$2:$I$108)/per_question!H8) | M8: =IF(H8=0,"",SUMIF(per_item!$D$2:$D$108,per_question!D8,per_item!$J$2:$J$108)/per_question!H8) | N8: 0 | O8: 0 | P8: =IF(AND(F8=TRUE,G8="API has data"),0,IF(AND(F8=TRUE,G8="API empty"),1,"")) -> 1 | Q8: =IF(AND(R8="Pos",S8="Pos"),"TP",IF(AND(R8="Neg",S8="Neg",P8=1),"TN",IF(AND(R8="Pos",S8="Neg"),"FN",IF(AND(R8="Neg",S8="Neg",P8=""),"FP","UNK")))) -> TN | R8: Neg | S8: =IF(AND(M8>=global_runs!$D$2,per_question!F8=FALSE),"Pos",IF(AND(M8<global_runs!$D$2,per_question!F8=FALSE),"Neg",IF(per_question!F8=TRUE,"Neg","Unknown"))) -> Neg | T8: 0.6 | U8: Maaf, saat ini tidak ada rumah yang tersedia di dekat Podomoro Medan dengan harga di bawah 1M. Namun, berikut adalah beberapa pilihan apartemen yang mungkin menarik untuk Anda: 1. **Dijual Cepat Apart | V8: {"keyword": "podomoro", "harga_max": 1000000000, "tipe_listing": 1, "jenis_properti": 1, "page": 1, "paginate": 5}
A9: 20251113-083353 | B9: 2025-11-13T08:33:53 | C9: test/test_vector_rval1.xlsx | D9: 8 | E9: TRUE | F9: FALSE | H9: =COUNTIF(per_item!$D$2:$D$108,per_question!D9) -> 5 | I9: =IF(H9=0,"",SUMIF(per_item!$D$2:$D$108,per_question!D9,per_item!$I$2:$I$108)/per_question!H9) -> 0.46666667 | J9: 1 | K9: 0.46666667 | L9: 0.63636364 | M9: =IF(H9=0,"",SUMIF(per_item!$D$2:$D$108,per_question!D9,per_item!$J$2:$J$108)/per_question!H9) -> 0 | N9: 15 | O9: 7 | P9: =IF(AND(F9=TRUE,G9="API has data"),0,IF(AND(F9=TRUE,G9="API empty"),1,"")) | Q9: =IF(AND(R9="Pos",S9="Pos"),"TP",IF(AND(R9="Neg",S9="Neg",P9=1),"TN",IF(AND(R9="Pos",S9="Neg"),"FN",IF(AND(R9="Neg",S9="Neg",P9=""),"FP","UNK")))) -> FP | R9: Neg | S9: =IF(AND(M9>=global_runs!$D$2,per_question!F9=FALSE),"Pos",IF(AND(M9<global_runs!$D$2,per_question!F9=FALSE),"Neg",IF(per_question!F9=TRUE,"Neg","Unknown"))) -> Neg | T9: 0.6 | U9: Berikut adalah beberapa pilihan properti sewa yang dekat dengan USU untuk anak Anda yang akan kuliah: 1. **Dijual Rumah Fully Furnish Setiabudi Dekat USU** - Lokasi: Jl. Abdul Hakim, Komp. Classic 3 S | V9: {"keyword": "usu", "tipe_listing": 2, "jenis_properti": 1, "page": 1, "paginate": 5}
A10: 20251113-083353 | B10: 2025-11-13T08:33:53 | C10: test/test_vector_rval1.xlsx | D10: 9 | E10: FALSE | F10: TRUE | G10: API empty | H10: =COUNTIF(per_item!$D$2:$D$108,per_question!D10) -> 0 | I10: =IF(H10=0,"",SUMIF(per_item!$D$2:$D$108,per_question!D10,per_item!$I$2:$I$108)/per_question!H10) | M10: =IF(H10=0,"",SUMIF(per_item!$D$2:$D$108,per_question!D10,per_item!$J$2:$J$108)/per_question!H10) | N10: 0 | O10: 0 | P10: =IF(AND(F10=TRUE,G10="API has data"),0,IF(AND(F10=TRUE,G10="API empty"),1,"")) -> 1 | Q10: =IF(AND(R10="Pos",S10="Pos"),"TP",IF(AND(R10="Neg",S10="Neg",P10=1),"TN",IF(AND(R10="Pos",S10="Neg"),"FN",IF(AND(R10="Neg",S10="Neg",P10=""),"FP","UNK")))) -> TN | R10: Neg | S10: =IF(AND(M10>=global_runs!$D$2,per_question!F10=FALSE),"Pos",IF(AND(M10<global_runs!$D$2,per_question!F10=FALSE),"Neg",IF(per_question!F10=TRUE,"Neg","Unknown"))) -> Neg | T10: 0.6 | U10: Berikut adalah pilihan rumah di inti kota Medan dengan harga di bawah 1M: 1. **Rumah Murah Di Marendal** - Lokasi: Jl. Cemp. Sari, Kel. Deli Tua, Kec. Deli Tua, Kota Medan - Harga: Rp 285.000.000 - Sp | V10: {"keyword": "inti kota medan", "harga_max": 1000000000, "tipe_listing": 1, "jenis_properti": 1, "page": 1, "paginate": 5}
A11: 20251113-083353 | B11: 2025-11-13T08:33:53 | C11: test/test_vector_rval1.xlsx | D11: 10 | E11: TRUE | F11: FALSE | H11: =COUNTIF(per_item!$D$2:$D$108,per_question!D11) -> 5 | I11: =IF(H11=0,"",SUMIF(per_item!$D$2:$D$108,per_question!D11,per_item!$I$2:$I$108)/per_question!H11) -> 0.66666667 | J11: 1 | K11: 0.66666667 | L11: 0.8 | M11: =IF(H11=0,"",SUMIF(per_item!$D$2:$D$108,per_question!D11,per_item!$J$2:$J$108)/per_question!H11) -> 0 | N11: 15 | O11: 10 | P11: =IF(AND(F11=TRUE,G11="API has data"),0,IF(AND(F11=TRUE,G11="API empty"),1,"")) | Q11: =IF(AND(R11="Pos",S11="Pos"),"TP",IF(AND(R11="Neg",S11="Neg",P11=1),"TN",IF(AND(R11="Pos",S11="Neg"),"FN",IF(AND(R11="Neg",S11="Neg",P11=""),"FP","UNK")))) -> FN | R11: Pos | S11: =IF(AND(M11>=global_runs!$D$2,per_question!F11=FALSE),"Pos",IF(AND(M11<global_runs!$D$2,per_question!F11=FALSE),"Neg",IF(per_question!F11=TRUE,"Neg","Unknown"))) -> Neg | T11: 0.6 | U11: Saat ini, saya tidak menemukan ruko yang disewakan di daerah Krakatau. Namun, berikut adalah beberapa pilihan ruko yang dijual di daerah tersebut: 1. **Di Jual Ruko Daerah Krakatau** - Lokasi: Jl. Ger | V11: {"keyword": "krakatau", "tipe_listing": 2, "jenis_properti": 2, "page": 1, "paginate": 5}
A12: 20251113-083353 | B12: 2025-11-13T08:33:53 | C12: test/test_vector_rval1.xlsx | D12: 11 | E12: TRUE | F12: FALSE | H12: =COUNTIF(per_item!$D$2:$D$108,per_question!D12) -> 5 | I12: =IF(H12=0,"",SUMIF(per_item!$D$2:$D$108,per_question!D12,per_item!$I$2:$I$108)/per_question!H12) -> 0.86666667 | J12: 1 | K12: 0.86666667 | L12: 0.92857143 | M12: =IF(H12=0,"",SUMIF(per_item!$D$2:$D$108,per_question!D12,per_item!$J$2:$J$108)/per_question!H12) -> 0.6 | N12: 15 | O12: 13 | P12: =IF(AND(F12=TRUE,G12="API has data"),0,IF(AND(F12=TRUE,G12="API empty"),1,"")) | Q12: =IF(AND(R12="Pos",S12="Pos"),"TP",IF(AND(R12="Neg",S12="Neg",P12=1),"TN",IF(AND(R12="Pos",S12="Neg"),"FN",IF(AND(R12="Neg",S12="Neg",P12=""),"FP","UNK")))) -> TP | R12: Pos | S12: =IF(AND(M12>=global_runs!$D$2,per_question!F12=FALSE),"Pos",IF(AND(M12<global_runs!$D$2,per_question!F12=FALSE),"Neg",IF(per_question!F12=TRUE,"Neg","Unknown"))) -> Pos | T12: 0.6 | U12: Berikut adalah beberapa pilihan tanah yang dijual di Marelan: 1. *Dijual tanah daerah Marelan* - Lokasi: Marelan, Kel. Tanah Enam Ratus, Kec. Medan Marelan, Kota Medan - Harga: Rp 7.000.000.000 - Spes | V12: {"keyword": "marelan", "tipe_listing": 1, "jenis_properti": 3, "page": 1, "paginate": 5}
A13: 20251113-083353 | B13: 2025-11-13T08:33:53 | C13: test/test_vector_rval1.xlsx | D13: 12 | E13: TRUE | F13: FALSE | H13: =COUNTIF(per_item!$D$2:$D$108,per_question!D13) -> 5 | I13: =IF(H13=0,"",SUMIF(per_item!$D$2:$D$108,per_question!D13,per_item!$I$2:$I$108)/per_question!H13) -> 0.5 | J13: 1 | K13: 0.5 | L13: 0.66666667 | M13: =IF(H13=0,"",SUMIF(per_item!$D$2:$D$108,per_question!D13,per_item!$J$2:$J$108)/per_question!H13) -> 0 | N13: 10 | O13: 5 | P13: =IF(AND(F13=TRUE,G13="API has data"),0,IF(AND(F13=TRUE,G13="API empty"),1,"")) | Q13: =IF(AND(R13="Pos",S13="Pos"),"TP",IF(AND(R13="Neg",S13="Neg",P13=1),"TN",IF(AND(R13="Pos",S13="Neg"),"FN",IF(AND(R13="Neg",S13="Neg",P13=""),"FP","UNK")))) -> FP | R13: Neg | S13: =IF(AND(M13>=global_runs!$D$2,per_question!F13=FALSE),"Pos",IF(AND(M13<global_runs!$D$2,per_question!F13=FALSE),"Neg",IF(per_question!F13=TRUE,"Neg","Unknown"))) -> Neg | T13: 0.6 | U13: Berikut adalah beberapa pilihan gudang yang tersedia di sekitar KIM: 1. **Gudang — Kab. Deli Serdang, Sumber Melati Diski** - Harga: Rp 2.200.000.000 - Spesifikasi: LT 1000 m², LB 180 m², carport 1 - | V13: {"keyword": "kim", "jenis_properti": 5, "page": 1, "paginate": 5}
A14: 20251113-083353 | B14: 2025-11-13T08:33:53 | C14: test/test_vector_rval1.xlsx | D14: 13 | E14: TRUE | F14: FALSE | H14: =COUNTIF(per_item!$D$2:$D$108,per_question!D14) -> 5 | I14: =IF(H14=0,"",SUMIF(per_item!$D$2:$D$108,per_question!D14,per_item!$I$2:$I$108)/per_question!H14) -> 0.9 | J14: 1 | K14: 0.9 | L14: 0.94736842 | M14: =IF(H14=0,"",SUMIF(per_item!$D$2:$D$108,per_question!D14,per_item!$J$2:$J$108)/per_question!H14) -> 0.4 | N14: 30 | O14: 27 | P14: =IF(AND(F14=TRUE,G14="API has data"),0,IF(AND(F14=TRUE,G14="API empty"),1,"")) | Q14: =IF(AND(R14="Pos",S14="Pos"),"TP",IF(AND(R14="Neg",S14="Neg",P14=1),"TN",IF(AND(R14="Pos",S14="Neg"),"FN",IF(AND(R14="Neg",S14="Neg",P14=""),"FP","UNK")))) -> FN | R14: Pos | S14: =IF(AND(M14>=global_runs!$D$2,per_question!F14=FALSE),"Pos",IF(AND(M14<global_runs!$D$2,per_question!F14=FALSE),"Neg",IF(per_question!F14=TRUE,"Neg","Unknown"))) -> Neg | T14: 0.6 | U14: Berikut adalah beberapa pilihan rumah yang dijual di daerah Ringroad dengan harga sekitar 1M dan memiliki 3 kamar: 1. **Dijual full perabot daerah Ringroad — Kota Medan, Tanjung Sari** - Harga: 900.00 | V14: {"keyword": "ringroad", "harga_min": 800000000, "harga_max": 1200000000, "kamar_tidur": 3, "tipe_listing": 1, "jenis_properti": 1, "page": 1, "paginate": 5}
A15: 20251113-083353 | B15: 2025-11-13T08:33:53 | C15: test/test_vector_rval1.xlsx | D15: 14 | E15: TRUE | F15: FALSE | H15: =COUNTIF(per_item!$D$2:$D$108,per_question!D15) -> 5 | I15: =IF(H15=0,"",SUMIF(per_item!$D$2:$D$108,per_question!D15,per_item!$I$2:$I$108)/per_question!H15) -> 0.86666667 | J15: 1 | K15: 0.86666667 | L15: 0.92857143 | M15: =IF(H15=0,"",SUMIF(per_item!$D$2:$D$108,per_question!D15,per_item!$J$2:$J$108)/per_question!H15) -> 0.2 | N15: 30 | O15: 26 | P15: =IF(AND(F15=TRUE,G15="API has data"),0,IF(AND(F15=TRUE,G15="API empty"),1,"")) | Q15: =IF(AND(R15="Pos",S15="Pos"),"TP",IF(AND(R15="Neg",S15="Neg",P15=1),"TN",IF(AND(R15="Pos",S15="Neg"),"FN",IF(AND(R15="Neg",S15="Neg",P15=""),"FP","UNK")))) -> FN | R15: Pos | S15: =IF(AND(M15>=global_runs!$D$2,per_question!F15=FALSE),"Pos",IF(AND(M15<global_runs!$D$2,per_question!F15=FALSE),"Neg",IF(per_question!F15=TRUE,"Neg","Unknown"))) -> Neg | T15: 0.6 | U15: Berikut adalah beberapa pilihan properti yang masih tersedia di daerah Ringroad, Kota Medan: 1. *Dijual Rumah Full Furnish di daerah Ringroad — Kota Medan, Sunggal* - Harga: 1.300.000.000 - Spesifikas | V15: {"keyword": "ringroad", "harga_min": 800000000, "harga_max": 1200000000, "kamar_tidur": 3, "tipe_listing": 1, "jenis_properti": 1, "page": 2, "paginate": 5}
A16: 20251113-083353 | B16: 2025-11-13T08:33:53 | C16: test/test_vector_rval1.xlsx | D16: 15 | E16: TRUE | F16: FALSE | H16: =COUNTIF(per_item!$D$2:$D$108,per_question!D16) -> 5 | I16: =IF(H16=0,"",SUMIF(per_item!$D$2:$D$108,per_question!D16,per_item!$I$2:$I$108)/per_question!H16) -> 0.86666667 | J16: 1 | K16: 0.86666667 | L16: 0.92857143 | M16: =IF(H16=0,"",SUMIF(per_item!$D$2:$D$108,per_question!D16,per_item!$J$2:$J$108)/per_question!H16) -> 0.2 | N16: 30 | O16: 26 | P16: =IF(AND(F16=TRUE,G16="API has data"),0,IF(AND(F16=TRUE,G16="API empty"),1,"")) | Q16: =IF(AND(R16="Pos",S16="Pos"),"TP",IF(AND(R16="Neg",S16="Neg",P16=1),"TN",IF(AND(R16="Pos",S16="Neg"),"FN",IF(AND(R16="Neg",S16="Neg",P16=""),"FP","UNK")))) -> FN | R16: Pos | S16: =IF(AND(M16>=global_runs!$D$2,per_question!F16=FALSE),"Pos",IF(AND(M16<global_runs!$D$2,per_question!F16=FALSE),"Neg",IF(per_question!F16=TRUE,"Neg","Unknown"))) -> Neg | T16: 0.6 | U16: Berikut adalah beberapa pilihan properti yang mungkin sesuai untuk Anda: 1. *Dijual Rumah Full Furnish di daerah Ringroad — Kota Medan, Sunggal* - Harga: 1.300.000.000 - Spesifikasi: 3 KT, 2 KM, LT 16 | V16: {"keyword": "ringroad", "harga_min": 800000000, "harga_max": 1200000000, "kamar_tidur": 3, "tipe_listing": 1, "jenis_properti": 1, "page": 3, "paginate": 5}
A17: 20251113-083353 | B17: 2025-11-13T08:33:53 | C17: test/test_vector_rval1.xlsx | D17: 16 | E17: TRUE | F17: FALSE | H17: =COUNTIF(per_item!$D$2:$D$108,per_question!D17) -> 1 | I17: =IF(H17=0,"",SUMIF(per_item!$D$2:$D$108,per_question!D17,per_item!$I$2:$I$108)/per_question!H17) -> 0.57142857 | J17: 1 | K17: 0.57142857 | L17: 0.72727273 | M17: =IF(H17=0,"",SUMIF(per_item!$D$2:$D$108,per_question!D17,per_item!$J$2:$J$108)/per_question!H17) -> 0 | N17: 7 | O17: 4 | P17: =IF(AND(F17=TRUE,G17="API has data"),0,IF(AND(F17=TRUE,G17="API empty"),1,"")) | Q17: =IF(AND(R17="Pos",S17="Pos"),"TP",IF(AND(R17="Neg",S17="Neg",P17=1),"TN",IF(AND(R17="Pos",S17="Neg"),"FN",IF(AND(R17="Neg",S17="Neg",P17=""),"FP","UNK")))) -> FN | R17: Pos | S17: =IF(AND(M17>=global_runs!$D$2,per_question!F17=FALSE),"Pos",IF(AND(M17<global_runs!$D$2,per_question!F17=FALSE),"Neg",IF(per_question!F17=TRUE,"Neg","Unknown"))) -> Neg | T17: 0.6 | U17: Berikut adalah pilihan properti 3 lantai di lokasi dan harga yang sama (Ringroad) yang mungkin sesuai dengan kebutuhan Anda: 1. **Dijual Ruko 2 gandeng di daerah Ringroad — Kota Medan, Sei Sikambing B | V17: {"keyword": "ringroad", "harga_min": 800000000, "harga_max": 1200000000, "kamar_tidur": 3, "tipe_listing": 1, "jenis_properti": 1, "jumlah_tingkat": 3, "page": 1, "paginate": 5}
A18: 20251113-083353 | B18: 2025-11-13T08:33:53 | C18: test/test_vector_rval1.xlsx | D18: 17 | E18: TRUE | F18: FALSE | H18: =COUNTIF(per_item!$D$2:$D$108,per_question!D18) -> 5 | I18: =IF(H18=0,"",SUMIF(per_item!$D$2:$D$108,per_question!D18,per_item!$I$2:$I$108)/per_question!H18) -> 0.74285714 | J18: 1 | K18: 0.74285714 | L18: 0.85245902 | M18: =IF(H18=0,"",SUMIF(per_item!$D$2:$D$108,per_question!D18,per_item!$J$2:$J$108)/per_question!H18) -> 0 | N18: 35 | O18: 26 | P18: =IF(AND(F18=TRUE,G18="API has data"),0,IF(AND(F18=TRUE,G18="API empty"),1,"")) | Q18: =IF(AND(R18="Pos",S18="Pos"),"TP",IF(AND(R18="Neg",S18="Neg",P18=1),"TN",IF(AND(R18="Pos",S18="Neg"),"FN",IF(AND(R18="Neg",S18="Neg",P18=""),"FP","UNK")))) -> FP | R18: Neg | S18: =IF(AND(M18>=global_runs!$D$2,per_question!F18=FALSE),"Pos",IF(AND(M18<global_runs!$D$2,per_question!F18=FALSE),"Neg",IF(per_question!F18=TRUE,"Neg","Unknown"))) -> Neg | T18: 0.6 | U18: Berikut adalah beberapa pilihan properti yang mungkin sesuai dengan permintaan Anda: 1. *Dijual Rumah Full Furnish di daerah Ringroad — Kota Medan, Sunggal* - Harga: 1.300.000.000 - Spesifikasi: 3 KT, | V18: {"keyword": "ringroad", "harga_min": 800000000, "harga_max": 1200000000, "kamar_tidur": 3, "tipe_listing": 1, "jenis_properti": 1, "jumlah_tingkat": 3, "page": 2, "paginate": 5}
A19: 20251113-083353 | B19: 2025-11-13T08:33:53 | C19: test/test_vector_rval1.xlsx | D19: 18 | E19: FALSE | F19: TRUE | G19: API has data | H19: =COUNTIF(per_item!$D$2:$D$108,per_question!D19) -> 0 | I19: =IF(H19=0,"",SUMIF(per_item!$D$2:$D$108,per_question!D19,per_item!$I$2:$I$108)/per_question!H19) | M19: =IF(H19=0,"",SUMIF(per_item!$D$2:$D$108,per_question!D19,per_item!$J$2:$J$108)/per_question!H19) | N19: 0 | O19: 0 | P19: =IF(AND(F19=TRUE,G19="API has data"),0,IF(AND(F19=TRUE,G19="API empty"),1,"")) -> 0 | Q19: =IF(AND(R19="Pos",S19="Pos"),"TP",IF(AND(R19="Neg",S19="Neg",P19=1),"TN",IF(AND(R19="Pos",S19="Neg"),"FN",IF(AND(R19="Neg",S19="Neg",P19=""),"FP","UNK")))) -> FN | R19: Pos | S19: =IF(AND(M19>=global_runs!$D$2,per_question!F19=FALSE),"Pos",IF(AND(M19<global_runs!$D$2,per_question!F19=FALSE),"Neg",IF(per_question!F19=TRUE,"Neg","Unknown"))) -> Neg | T19: 0.6 | U19: Maaf, berdasarkan data yang ada, tidak ada properti dengan lokasi dan jumlah lantai yang sama di bawah 800 juta. Apakah ada kata kunci lain yang ingin Anda cari atau mungkin Anda ingin mengubah kriter | V19: {"keyword": "ringroad", "harga_max": 800000000, "kamar_tidur": 3, "tipe_listing": 1, "jenis_properti": 1, "jumlah_tingkat": 3, "page": 1, "paginate": 5}
A20: 20251113-083353 | B20: 2025-11-13T08:33:53 | C20: test/test_vector_rval1.xlsx | D20: 19 | E20: TRUE | F20: FALSE | H20: =COUNTIF(per_item!$D$2:$D$108,per_question!D20) -> 2 | I20: =IF(H20=0,"",SUMIF(per_item!$D$2:$D$108,per_question!D20,per_item!$I$2:$I$108)/per_question!H20) -> 1 | J20: 1 | K20: 1 | L20: 1 | M20: =IF(H20=0,"",SUMIF(per_item!$D$2:$D$108,per_question!D20,per_item!$J$2:$J$108)/per_question!H20) -> 1 | N20: 4 | O20: 4 | P20: =IF(AND(F20=TRUE,G20="API has data"),0,IF(AND(F20=TRUE,G20="API empty"),1,"")) | Q20: =IF(AND(R20="Pos",S20="Pos"),"TP",IF(AND(R20="Neg",S20="Neg",P20=1),"TN",IF(AND(R20="Pos",S20="Neg"),"FN",IF(AND(R20="Neg",S20="Neg",P20=""),"FP","UNK")))) -> TP | R20: Pos | S20: =IF(AND(M20>=global_runs!$D$2,per_question!F20=FALSE),"Pos",IF(AND(M20<global_runs!$D$2,per_question!F20=FALSE),"Neg",IF(per_question!F20=TRUE,"Neg","Unknown"))) -> Pos | T20: 0.6 | U20: Berikut adalah beberapa pilihan rumah di Medan yang dilengkapi dengan fasilitas CCTV: 1. **Dijual Rumah Mewah Full Furnished Kawasan Simpang Pemda Medan** - Lokasi: Jl. Flamboyan I/2, Kel. Tanjung Sel | V20: {"keyword": "medan", "info_lainnya": "cctv"}
A21: 20251113-083353 | B21: 2025-11-13T08:33:53 | C21: test/test_vector_rval1.xlsx | D21: 20 | E21: TRUE | F21: FALSE | H21: =COUNTIF(per_item!$D$2:$D$108,per_question!D21) -> 5 | I21: =IF(H21=0,"",SUMIF(per_item!$D$2:$D$108,per_question!D21,per_item!$I$2:$I$108)/per_question!H21) -> 0.6 | J21: 1 | K21: 0.6 | L21: 0.75 | M21: =IF(H21=0,"",SUMIF(per_item!$D$2:$D$108,per_question!D21,per_item!$J$2:$J$108)/per_question!H21) -> 0.2 | N21: 10 | O21: 6 | P21: =IF(AND(F21=TRUE,G21="API has data"),0,IF(AND(F21=TRUE,G21="API empty"),1,"")) | Q21: =IF(AND(R21="Pos",S21="Pos"),"TP",IF(AND(R21="Neg",S21="Neg",P21=1),"TN",IF(AND(R21="Pos",S21="Neg"),"FN",IF(AND(R21="Neg",S21="Neg",P21=""),"FP","UNK")))) -> FN | R21: Pos | S21: =IF(AND(M21>=global_runs!$D$2,per_question!F21=FALSE),"Pos",IF(AND(M21<global_runs!$D$2,per_question!F21=FALSE),"Neg",IF(per_question!F21=TRUE,"Neg","Unknown"))) -> Neg | T21: 0.6 | U21: Berikut adalah beberapa pilihan rumah di Medan yang dilengkapi dengan fasilitas WiFi: 1. *Dijual Rumah Mewah Full Furnished Kawasan Simpang Pemda Medan* - Lokasi: Jl. Flamboyan I/2, Kel. Tanjung Selam | V21: {"keyword": "medan", "info_lainnya": "wifi"}
A22: 20251113-083353 | B22: 2025-11-13T08:33:53 | C22: test/test_vector_rval1.xlsx | D22: 21 | E22: TRUE | F22: FALSE | H22: =COUNTIF(per_item!$D$2:$D$108,per_question!D22) -> 2 | I22: =IF(H22=0,"",SUMIF(per_item!$D$2:$D$108,per_question!D22,per_item!$I$2:$I$108)/per_question!H22) -> 0.5 | J22: 1 | K22: 0.5 | L22: 0.66666667 | M22: =IF(H22=0,"",SUMIF(per_item!$D$2:$D$108,per_question!D22,per_item!$J$2:$J$108)/per_question!H22) -> 0.5 | N22: 2 | O22: 1 | P22: =IF(AND(F22=TRUE,G22="API has data"),0,IF(AND(F22=TRUE,G22="API empty"),1,"")) | Q22: =IF(AND(R22="Pos",S22="Pos"),"TP",IF(AND(R22="Neg",S22="Neg",P22=1),"TN",IF(AND(R22="Pos",S22="Neg"),"FN",IF(AND(R22="Neg",S22="Neg",P22=""),"FP","UNK")))) -> FN | R22: Pos | S22: =IF(AND(M22>=global_runs!$D$2,per_question!F22=FALSE),"Pos",IF(AND(M22<global_runs!$D$2,per_question!F22=FALSE),"Neg",IF(per_question!F22=TRUE,"Neg","Unknown"))) -> Neg | T22: 0.6 | U22: Berikut adalah pilihan rumah dalam komplek yang memiliki fasilitas lapangan basket: 1. *Dijual Rumah Dalam Komplek Elite Full Furnished* Lokasi: Jl. Flamboyan I, komp. Taman asoka asri, Kel. Tanjung S | V22: {"info_lainnya": "basket"}
A23: 20251113-083353 | B23: 2025-11-13T08:33:53 | C23: test/test_vector_rval1.xlsx | D23: 22 | E23: TRUE | F23: FALSE | H23: =COUNTIF(per_item!$D$2:$D$108,per_question!D23) -> 5 | I23: =IF(H23=0,"",SUMIF(per_item!$D$2:$D$108,per_question!D23,per_item!$I$2:$I$108)/per_question!H23) -> 1 | J23: 1 | K23: 0.2 | L23: 0.33333333 | M23: =IF(H23=0,"",SUMIF(per_item!$D$2:$D$108,per_question!D23,per_item!$J$2:$J$108)/per_question!H23) -> 1 | N23: 5 | O23: 1 | P23: =IF(AND(F23=TRUE,G23="API has data"),0,IF(AND(F23=TRUE,G23="API empty"),1,"")) | Q23: =IF(AND(R23="Pos",S23="Pos"),"TP",IF(AND(R23="Neg",S23="Neg",P23=1),"TN",IF(AND(R23="Pos",S23="Neg"),"FN",IF(AND(R23="Neg",S23="Neg",P23=""),"FP","UNK")))) -> TP | R23: Pos | S23: =IF(AND(M23>=global_runs!$D$2,per_question!F23=FALSE),"Pos",IF(AND(M23<global_runs!$D$2,per_question!F23=FALSE),"Neg",IF(per_question!F23=TRUE,"Neg","Unknown"))) -> Pos | T23: 0.6 | U23: Berikut adalah beberapa pilihan rumah yang dapat parkir beberapa mobil: 1. **Dijual Rumah Hook Luas Di Ringroad** - Lokasi: Jl. Taman Perkasa Indah, Komp. taman perkasa indah, Kota Medan - Harga: 2.50 | V23: {"info_lainnya": "parkir"}
A24: 20251113-083353 | B24: 2025-11-13T08:33:53 | C24: test/test_vector_rval1.xlsx | D24: 23 | E24: TRUE | F24: FALSE | H24: =COUNTIF(per_item!$D$2:$D$108,per_question!D24) -> 5 | I24: =IF(H24=0,"",SUMIF(per_item!$D$2:$D$108,per_question!D24,per_item!$I$2:$I$108)/per_question!H24) -> 0.6 | J24: 1 | K24: 0.6 | L24: 0.75 | M24: =IF(H24=0,"",SUMIF(per_item!$D$2:$D$108,per_question!D24,per_item!$J$2:$J$108)/per_question!H24) -> 0.6 | N24: 5 | O24: 3 | P24: =IF(AND(F24=TRUE,G24="API has data"),0,IF(AND(F24=TRUE,G24="API empty"),1,"")) | Q24: =IF(AND(R24="Pos",S24="Pos"),"TP",IF(AND(R24="Neg",S24="Neg",P24=1),"TN",IF(AND(R24="Pos",S24="Neg"),"FN",IF(AND(R24="Neg",S24="Neg",P24=""),"FP","UNK")))) -> TP | R24: Pos | S24: =IF(AND(M24>=global_runs!$D$2,per_question!F24=FALSE),"Pos",IF(AND(M24<global_runs!$D$2,per_question!F24=FALSE),"Neg",IF(per_question!F24=TRUE,"Neg","Unknown"))) -> Pos | T24: 0.6 | U24: Berikut adalah pilihan rumah yang sesuai dengan kriteria Anda, yaitu sudah dilengkapi dengan AC, lemari, dapur, dan tangki air: 1. *Rumah Komp. Karya Setuju* — Kota Medan, Karang Berombak Harga: 850.0 | V24: {"info_lainnya": "tangki air"}
A25: 20251113-083353 | B25: 2025-11-13T08:33:53 | C25: test/test_vector_rval1.xlsx | D25: 24 | E25: TRUE | F25: FALSE | H25: =COUNTIF(per_item!$D$2:$D$108,per_question!D25) -> 5 | I25: =IF(H25=0,"",SUMIF(per_item!$D$2:$D$108,per_question!D25,per_item!$I$2:$I$108)/per_question!H25) -> 1 | J25: 1 | K25: 0.4 | L25: 0.57142857 | M25: =IF(H25=0,"",SUMIF(per_item!$D$2:$D$108,per_question!D25,per_item!$J$2:$J$108)/per_question!H25) -> 1 | N25: 5 | O25: 2 | P25: =IF(AND(F25=TRUE,G25="API has data"),0,IF(AND(F25=TRUE,G25="API empty"),1,"")) | Q25: =IF(AND(R25="Pos",S25="Pos"),"TP",IF(AND(R25="Neg",S25="Neg",P25=1),"TN",IF(AND(R25="Pos",S25="Neg"),"FN",IF(AND(R25="Neg",S25="Neg",P25=""),"FP","UNK")))) -> TP | R25: Pos | S25: =IF(AND(M25>=global_runs!$D$2,per_question!F25=FALSE),"Pos",IF(AND(M25<global_runs!$D$2,per_question!F25=FALSE),"Neg",IF(per_question!F25=TRUE,"Neg","Unknown"))) -> Pos | T25: 0.6 | U25: Berikut adalah beberapa pilihan rumah yang dekat dengan mall: 1. *Dijual Rumah Cantik dekat Mall daerah Ringroad* - Lokasi: Jl. Bayu, Komp. The Living Harmony, Kel. Tanjung Rejo, Kec. Medan Sunggal, K | V25: {"info_lainnya": "mall"}
A26: 20251113-083353 | B26: 2025-11-13T08:33:53 | C26: test/test_vector_rval1.xlsx | D26: 25 | E26: TRUE | F26: FALSE | H26: =COUNTIF(per_item!$D$2:$D$108,per_question!D26) -> 5 | I26: =IF(H26=0,"",SUMIF(per_item!$D$2:$D$108,per_question!D26,per_item!$I$2:$I$108)/per_question!H26) -> 0.8 | J26: 1 | K26: 0.8 | L26: 0.88888889 | M26: =IF(H26=0,"",SUMIF(per_item!$D$2:$D$108,per_question!D26,per_item!$J$2:$J$108)/per_question!H26) -> 0.8 | N26: 5 | O26: 4 | P26: =IF(AND(F26=TRUE,G26="API has data"),0,IF(AND(F26=TRUE,G26="API empty"),1,"")) | Q26: =IF(AND(R26="Pos",S26="Pos"),"TP",IF(AND(R26="Neg",S26="Neg",P26=1),"TN",IF(AND(R26="Pos",S26="Neg"),"FN",IF(AND(R26="Neg",S26="Neg",P26=""),"FP","UNK")))) -> TP | R26: Pos | S26: =IF(AND(M26>=global_runs!$D$2,per_question!F26=FALSE),"Pos",IF(AND(M26<global_runs!$D$2,per_question!F26=FALSE),"Neg",IF(per_question!F26=TRUE,"Neg","Unknown"))) -> Pos | T26: 0.6 | U26: Berikut adalah beberapa pilihan rumah yang dekat dengan sekolah di Medan: 1. *Dijual rumah dekat Sekolah — Kota Medan, Binjai* - Lokasi: Jl. Sepakat, gg Bersama, Kel. Binjai, Kec. Medan Denai - Harga: | V26: {"info_lainnya": "sekolah"}
A27: 20251113-083353 | B27: 2025-11-13T08:33:53 | C27: test/test_vector_rval1.xlsx | D27: 26 | E27: TRUE | F27: FALSE | H27: =COUNTIF(per_item!$D$2:$D$108,per_question!D27) -> 5 | I27: =IF(H27=0,"",SUMIF(per_item!$D$2:$D$108,per_question!D27,per_item!$I$2:$I$108)/per_question!H27) -> 0.8 | J27: 1 | K27: 0.6 | L27: 0.75 | M27: =IF(H27=0,"",SUMIF(per_item!$D$2:$D$108,per_question!D27,per_item!$J$2:$J$108)/per_question!H27) -> 0.6 | N27: 10 | O27: 6 | P27: =IF(AND(F27=TRUE,G27="API has data"),0,IF(AND(F27=TRUE,G27="API empty"),1,"")) | Q27: =IF(AND(R27="Pos",S27="Pos"),"TP",IF(AND(R27="Neg",S27="Neg",P27=1),"TN",IF(AND(R27="Pos",S27="Neg"),"FN",IF(AND(R27="Neg",S27="Neg",P27=""),"FP","UNK")))) -> TP | R27: Pos | S27: =IF(AND(M27>=global_runs!$D$2,per_question!F27=FALSE),"Pos",IF(AND(M27<global_runs!$D$2,per_question!F27=FALSE),"Neg",IF(per_question!F27=TRUE,"Neg","Unknown"))) -> Pos | T27: 0.6 | U27: Berikut adalah pilihan rumah dekat mall dengan harga di bawah 800 juta: 1. *Rumah Murah Di Kawasan Millenium* - Lokasi: Jl. Bakti Luhur, Kota Medan - Harga: 700.000.000 - Spesifikasi: 4 KT, 3 KM, LT 8 | V27: {"info_lainnya": "mall", "harga_max": 800000000}
A28: 20251113-083353 | B28: 2025-11-13T08:33:53 | C28: test/test_vector_rval1.xlsx | D28: 27 | E28: TRUE | F28: FALSE | H28: =COUNTIF(per_item!$D$2:$D$108,per_question!D28) -> 2 | I28: =IF(H28=0,"",SUMIF(per_item!$D$2:$D$108,per_question!D28,per_item!$I$2:$I$108)/per_question!H28) -> 0.75 | J28: 1 | K28: 0.75 | L28: 0.85714286 | M28: =IF(H28=0,"",SUMIF(per_item!$D$2:$D$108,per_question!D28,per_item!$J$2:$J$108)/per_question!H28) -> 0.5 | N28: 4 | O28: 3 | P28: =IF(AND(F28=TRUE,G28="API has data"),0,IF(AND(F28=TRUE,G28="API empty"),1,"")) | Q28: =IF(AND(R28="Pos",S28="Pos"),"TP",IF(AND(R28="Neg",S28="Neg",P28=1),"TN",IF(AND(R28="Pos",S28="Neg"),"FN",IF(AND(R28="Neg",S28="Neg",P28=""),"FP","UNK")))) -> FN | R28: Pos | S28: =IF(AND(M28>=global_runs!$D$2,per_question!F28=FALSE),"Pos",IF(AND(M28<global_runs!$D$2,per_question!F28=FALSE),"Neg",IF(per_question!F28=TRUE,"Neg","Unknown"))) -> Neg | T28: 0.6 | U28: Berikut adalah pilihan rumah full furnished yang harganya di bawah 1 M dan berada dalam komplek dengan fasilitas lapangan basket: 1. **Dijual Rumah Dalam Komplek Elite Full Furnished** - Lokasi: Jl. F | V28: {"info_lainnya": "basket", "harga_max": 1000000000}
A29: 20251113-083353 | B29: 2025-11-13T08:33:53 | C29: test/test_vector_rval1.xlsx | D29: 28 | E29: TRUE | F29: FALSE | H29: =COUNTIF(per_item!$D$2:$D$108,per_question!D29) -> 5 | I29: =IF(H29=0,"",SUMIF(per_item!$D$2:$D$108,per_question!D29,per_item!$I$2:$I$108)/per_question!H29) -> 1 | J29: 1 | K29: 1 | L29: 1 | M29: =IF(H29=0,"",SUMIF(per_item!$D$2:$D$108,per_question!D29,per_item!$J$2:$J$108)/per_question!H29) -> 1 | N29: 10 | O29: 10 | P29: =IF(AND(F29=TRUE,G29="API has data"),0,IF(AND(F29=TRUE,G29="API empty"),1,"")) | Q29: =IF(AND(R29="Pos",S29="Pos"),"TP",IF(AND(R29="Neg",S29="Neg",P29=1),"TN",IF(AND(R29="Pos",S29="Neg"),"FN",IF(AND(R29="Neg",S29="Neg",P29=""),"FP","UNK")))) -> TP | R29: Pos | S29: =IF(AND(M29>=global_runs!$D$2,per_question!F29=FALSE),"Pos",IF(AND(M29<global_runs!$D$2,per_question!F29=FALSE),"Neg",IF(per_question!F29=TRUE,"Neg","Unknown"))) -> Pos | T29: 0.6 | U29: Berikut adalah beberapa pilihan apartemen di Podomoro dengan harga di bawah 1.5 M: 1. *Dijual Cepat Apartment Podomoro* - Harga: 1.350.000.000 - Spesifikasi: 1 KT, 1 KM, LT 41 m², carport 1 - Link: ht | V29: {"keyword": "podomoro", "harga_max": 1500000000}
A30: 20251113-083353 | B30: 2025-11-13T08:33:53 | C30: test/test_vector_rval1.xlsx | D30: 29 | E30: TRUE | F30: FALSE | H30: =COUNTIF(per_item!$D$2:$D$108,per_question!D30) -> 5 | I30: =IF(H30=0,"",SUMIF(per_item!$D$2:$D$108,per_question!D30,per_item!$I$2:$I$108)/per_question!H30) -> 1 | J30: 1 | K30: 1 | L30: 1 | M30: =IF(H30=0,"",SUMIF(per_item!$D$2:$D$108,per_question!D30,per_item!$J$2:$J$108)/per_question!H30) -> 1 | N30: 5 | O30: 5 | P30: =IF(AND(F30=TRUE,G30="API has data"),0,IF(AND(F30=TRUE,G30="API empty"),1,"")) | Q30: =IF(AND(R30="Pos",S30="Pos"),"TP",IF(AND(R30="Neg",S30="Neg",P30=1),"TN",IF(AND(R30="Pos",S30="Neg"),"FN",IF(AND(R30="Neg",S30="Neg",P30=""),"FP","UNK")))) -> TP | R30: Pos | S30: =IF(AND(M30>=global_runs!$D$2,per_question!F30=FALSE),"Pos",IF(AND(M30<global_runs!$D$2,per_question!F30=FALSE),"Neg",IF(per_question!F30=TRUE,"Neg","Unknown"))) -> Pos | T30: 0.6 | U30: Berikut adalah beberapa pilihan rumah yang tersedia di Citraland Bagya City, Medan: 1. *Dijual rumah kompleks Citraland Bagya City* - Lokasi: Ismail Harun, komp. Citraland Bagya City, Kel. Kenangan Ba | V30: {"keyword": "citraland bagya city"}
A31: 20251113-083353 | B31: 2025-11-13T08:33:53 | C31: test/test_vector_rval1.xlsx | D31: 30 | E31: TRUE | F31: FALSE | H31: =COUNTIF(per_item!$D$2:$D$108,per_question!D31) -> 5 | I31: =IF(H31=0,"",SUMIF(per_item!$D$2:$D$108,per_question!D31,per_item!$I$2:$I$108)/per_question!H31) -> 1 | J31: 1 | K31: 1 | L31: 1 | M31: =IF(H31=0,"",SUMIF(per_item!$D$2:$D$108,per_question!D31,per_item!$J$2:$J$108)/per_question!H31) -> 1 | N31: 15 | O31: 15 | P31: =IF(AND(F31=TRUE,G31="API has data"),0,IF(AND(F31=TRUE,G31="API empty"),1,"")) | Q31: =IF(AND(R31="Pos",S31="Pos"),"TP",IF(AND(R31="Neg",S31="Neg",P31=1),"TN",IF(AND(R31="Pos",S31="Neg"),"FN",IF(AND(R31="Neg",S31="Neg",P31=""),"FP","UNK")))) -> TP | R31: Pos | S31: =IF(AND(M31>=global_runs!$D$2,per_question!F31=FALSE),"Pos",IF(AND(M31<global_runs!$D$2,per_question!F31=FALSE),"Neg",IF(per_question!F31=TRUE,"Neg","Unknown"))) -> Pos | T31: 0.6 | U31: Berikut adalah beberapa pilihan rumah yang dijual di Komplek Givency One: 1. *Dijual komplek givency one siaphuni type vercase* - Lokasi: Jl. Gaperta Ujung, Kel. Tj. Gusta, Kec. Medan Helvetia, Kota M | V31: {"keyword": "givency one", "tipe_listing": 1, "jenis_properti": 1}
I32: =AVERAGE(I2:I31) -> 0.8172381 | J32: =AVERAGE(J2:J31) -> 1 | K32: =AVERAGE(K2:K31) -> 0.7532381 | L32: =AVERAGE(L2:L31) -> 0.83795289 | M32: =AVERAGE(M2:M31) -> 0.57066667 | P32: =AVERAGE(P2:P31) -> 0.4
B33: = | C33: copy data dari file yang digenerate python | S33: =COUNTIF(S2:S31,"Pos") -> 14
A34: sheet per_item | C34: copy data dari file yang digenerate python

Sheet per_item
A1: run_id | B1: run_ts | C1: xls_input | D1: q_index | E1: item_idx | F1: title | G1: link | H1: listing_id | I1: per_constraint_accuracy | J1: strict_success | K1: price | L1: kamar_tidur | M1: luas_bangunan | N1: luas_tanah | O1: lebar_bangunan | P1: jumlah_tingkat | Q1: kondisi | R1: jenis_properti | S1: tipe_listing | T1: mata_angin | U1: pred_json
A2: 20251113-083353 | B2: 2025-11-13T08:33:53 | C2: test/test_vector_rval1.xlsx | D2: 1 | E2: 1 | F2: *Dijual Rumah di Jl. Cemara, Kota Medan | G2: https://metaproperty.co.id/listing/9878 | H2: 9878 | I2: 1 | J2: 1 | K2: 695000000 | M2: 120 | N2: 76 | P2: 2 | R2: 1 | S2: 1 | T2: barat | U2: {"keyword": true, "jenis_properti": true, "tipe_listing": true}
A3: 20251113-083353 | B3: 2025-11-13T08:33:53 | C3: test/test_vector_rval1.xlsx | D3: 1 | E3: 2 | F3: *Dijual Rumah di Gg. Tusam, Kota Medan | G3: https://metaproperty.co.id/listing/8341 | H3: 8341 | I3: 1 | J3: 1 | K3: 1000000000 | L3: 2 | M3: 168 | N3: 64 | P3: 3 | R3: 1 | S3: 1 | T3: selatan | U3: {"keyword": true, "jenis_properti": true, "tipe_listing": true}
A4: 20251113-083353 | B4: 2025-11-13T08:33:53 | C4: test/test_vector_rval1.xlsx | D4: 1 | E4: 3 | F4: *Dijual Rumah di Lrg. II Timur, Medan Estate | G4: https://metaproperty.co.id/listing/7426 | H4: 7426 | I4: 1 | J4: 1 | K4: 760000000 | M4: 95 | N4: 55 | P4: 2 | R4: 1 | S4: 1 | T4: timur | U4: {"keyword": true, "jenis_properti": true, "tipe_listing": true}
A5: 20251113-083353 | B5: 2025-11-13T08:33:53 | C5: test/test_vector_rval1.xlsx | D5: 1 | E5: 4 | F5: *Dijual Rumah Semi Furnished di Jl. Anggrek, Medan Estate | G5: https://metaproperty.co.id/listing/9278 | H5: 9278 | I5: 1 | J5: 1 | K5: 8500000000 | L5: 5 | M5: 720 | N5: 300 | P5: 3 | Q5: non furnished | R5: 1 | S5: 1 | T5: selatan | U5: {"keyword": true, "jenis_properti": true, "tipe_listing": true}
A6: 20251113-083353 | B6: 2025-11-13T08:33:53 | C6: test/test_vector_rval1.xlsx | D6: 1 | E6: 5 | F6: *Dijual Rumah Bertingkat di Jl. Perwakilan I, Kota Medan | G6: https://metaproperty.co.id/listing/9275 | H6: 9275 | I6: 1 | J6: 1 | K6: 850000000 | L6: 3 | M6: 150 | N6: 112 | P6: 2 | R6: 1 | S6: 1 | T6: timur | U6: {"keyword": true, "jenis_properti": true, "tipe_listing": true}
A7: 20251113-083353 | B7: 2025-11-13T08:33:53 | C7: test/test_vector_rval1.xlsx | D7: 2 | E7: 1 | F7: *Dijual full perabot daerah Ringroad | G7: https://metaproperty.co.id/listing/7980 | H7: 7980 | I7: 1 | J7: 1 | K7: 900000000 | L7: 3 | M7: 90 | N7: 90 | P7: 2 | R7: 1 | S7: 1 | T7: barat | U7: {"keyword": true, "jenis_properti": true, "tipe_listing": true}
A8: 20251113-083353 | B8: 2025-11-13T08:33:53 | C8: test/test_vector_rval1.xlsx | D8: 2 | E8: 2 | F8: *Dijual Rumah Full Furnish di daerah Ringroad | G8: https://metaproperty.co.id/listing/9821 | H8: 9821 | I8: 1 | J8: 1 | K8: 1300000000 | L8: 3 | M8: 140 | N8: 162 | P8: 2 | R8: 1 | S8: 1 | U8: {"keyword": true, "jenis_properti": true, "tipe_listing": true}
A9: 20251113-083353 | B9: 2025-11-13T08:33:53 | C9: test/test_vector_rval1.xlsx | D9: 2 | E9: 3 | F9: *Dijual Rumah Cantik Full Furnish Daerah Ringroad | G9: https://metaproperty.co.id/listing/9724 | H9: 9724 | I9: 1 | J9: 1 | K9: 1300000000 | L9: 3 | M9: 144 | N9: 84 | P9: 2 | R9: 1 | S9: 1 | U9: {"keyword": true, "jenis_properti": true, "tipe_listing": true}
A10: 20251113-083353 | B10: 2025-11-13T08:33:53 | C10: test/test_vector_rval1.xlsx | D10: 2 | E10: 4 | F10: *Dijual Cepat Rumah Luas di daerah RingRoad | G10: https://metaproperty.co.id/listing/7329 | H10: 7329 | I10: 1 | J10: 1 | K10: 950000000 | L10: 4 | M10: 192 | N10: 96 | P10: 2 | R10: 1 | S10: 1 | T10: utara | U10: {"keyword": true, "jenis_properti": true, "tipe_listing": true}
A11: 20251113-083353 | B11: 2025-11-13T08:33:53 | C11: test/test_vector_rval1.xlsx | D11: 2 | E11: 5 | F11: *Dijual Rumah Hook Luas Di Ringroad | G11: https://metaproperty.co.id/listing/9826 | H11: 9826 | I11: 1 | J11: 1 | K11: 2500000000 | L11: 6 | M11: 300 | N11: 368 | P11: 2 | R11: 1 | S11: 1 | T11: timur | U11: {"keyword": true, "jenis_properti": true, "tipe_listing": true}
A12: 20251113-083353 | B12: 2025-11-13T08:33:53 | C12: test/test_vector_rval1.xlsx | D12: 3 | E12: 1 | F12: *Disewakan Rumah di Royal Sumatera | G12: https://metaproperty.co.id/listing/9976 | H12: 9976 | I12: 1 | J12: 1 | K12: 60000000 | L12: 3 | M12: 180 | N12: 135 | P12: 2 | R12: 1 | S12: 2 | T12: timur | U12: {"keyword": true, "jenis_properti": true, "tipe_listing": true}
A13: 20251113-083353 | B13: 2025-11-13T08:33:53 | C13: test/test_vector_rval1.xlsx | D13: 3 | E13: 2 | F13: *Disewakan Rumah Cantik Full Furnished | G13: https://metaproperty.co.id/listing/6091 | H13: 6091 | I13: 1 | J13: 1 | K13: 180000000 | L13: 6 | M13: 600 | N13: 300 | P13: 2 | Q13: full furnished | R13: 1 | S13: 2 | U13: {"keyword": true, "jenis_properti": true, "tipe_listing": true}
A14: 20251113-083353 | B14: 2025-11-13T08:33:53 | C14: test/test_vector_rval1.xlsx | D14: 4 | E14: 1 | F14: *Dijual Rumah daerah Cemara | G14: https://metaproperty.co.id/listing/9878 | H14: 9878 | I14: 0.8 | J14: 0 | K14: 695000000 | M14: 120 | N14: 76 | P14: 2 | R14: 1 | S14: 1 | T14: barat | U14: {"keyword": true, "harga_min": false, "harga_max": true, "jenis_properti": true, "tipe_listing": true}
A15: 20251113-083353 | B15: 2025-11-13T08:33:53 | C15: test/test_vector_rval1.xlsx | D15: 4 | E15: 2 | F15: *Dijual Rumah Bertingkat daerah Cemara | G15: https://metaproperty.co.id/listing/9275 | H15: 9275 | I15: 1 | J15: 1 | K15: 850000000 | L15: 3 | M15: 150 | N15: 112 | P15: 2 | Q15: baru | R15: 1 | S15: 1 | T15: timur | U15: {"keyword": true, "harga_min": true, "harga_max": true, "jenis_properti": true, "tipe_listing": true}
A16: 20251113-083353 | B16: 2025-11-13T08:33:53 | C16: test/test_vector_rval1.xlsx | D16: 4 | E16: 3 | F16: *Dijual Rumah di Gg. Tusam | G16: https://metaproperty.co.id/listing/8341 | H16: 8341 | I16: 1 | J16: 1 | K16: 1000000000 | L16: 2 | M16: 168 | N16: 64 | P16: 3 | R16: 1 | S16: 1 | T16: selatan | U16: {"keyword": true, "harga_min": true, "harga_max": true, "jenis_properti": true, "tipe_listing": true}
A17: 20251113-083353 | B17: 2025-11-13T08:33:53 | C17: test/test_vector_rval1.xlsx | D17: 8 | E17: 1 | F17: *Dijual Rumah Fully Furnish Setiabudi Dekat USU | G17: https://metaproperty.co.id/listing/9091 | H17: 9091 | I17: 0.66666667 | J17: 0 | K17: 1500000000 | L17: 4 | M17: 269 | N17: 105 | P17: 3 | R17: 1 | S17: 1 | T17: timur | U17: {"keyword": true, "jenis_properti": true, "tipe_listing": false}
A18: 20251113-083353 | B18: 2025-11-13T08:33:53 | C18: test/test_vector_rval1.xlsx | D18: 8 | E18: 2 | F18: *Dijual Rumah Cantik di Setia Budi Full Furnish | G18: https://metaproperty.co.id/listing/9209 | H18: 9209 | I18: 0.66666667 | J18: 0 | K18: 1450000000 | L18: 3 | M18: 315 | N18: 150 | P18: 3 | R18: 1 | S18: 1 | T18: barat | U18: {"keyword": true, "jenis_properti": true, "tipe_listing": false}
A19: 20251113-083353 | B19: 2025-11-13T08:33:53 | C19: test/test_vector_rval1.xlsx | D19: 8 | E19: 3 | F19: *Dijual Rumah Dekat Kampus UMN | G19: https://metaproperty.co.id/listing/6938 | H19: 6938 | I19: 0.33333333 | J19: 0 | K19: 465000000 | L19: 2 | M19: 44 | N19: 186 | P19: 1 | R19: 1 | S19: 1 | T19: barat | U19: {"keyword": false, "jenis_properti": true, "tipe_listing": false}
A20: 20251113-083353 | B20: 2025-11-13T08:33:53 | C20: test/test_vector_rval1.xlsx | D20: 8 | E20: 4 | F20: *Dijual Rumah 2 Lantai dekat UMSU | G20: https://metaproperty.co.id/listing/6920 | H20: 6920 | I20: 0.33333333 | J20: 0 | K20: 3900000000 | L20: 4 | M20: 300 | N20: 184 | P20: 2 | R20: 1 | S20: 1 | T20: utara | U20: {"keyword": false, "jenis_properti": true, "tipe_listing": false}
A21: 20251113-083353 | B21: 2025-11-13T08:33:53 | C21: test/test_vector_rval1.xlsx | D21: 8 | E21: 5 | F21: *Dijual Rumah Besar Lahan Luas dekat UMSU | G21: https://metaproperty.co.id/listing/1122 | H21: 1122 | I21: 0.33333333 | J21: 0 | K21: 1300000000 | L21: 3 | M21: 200 | N21: 419 | P21: 1 | R21: 1 | S21: 1 | U21: {"keyword": false, "jenis_properti": true, "tipe_listing": false}
A22: 20251113-083353 | B22: 2025-11-13T08:33:53 | C22: test/test_vector_rval1.xlsx | D22: 10 | E22: 1 | F22: *Di Jual Ruko Daerah Krakatau | G22: https://metaproperty.co.id/listing/8560 | H22: 8560 | I22: 0.66666667 | J22: 0 | K22: 850000000 | L22: 2 | M22: 210 | N22: 70 | P22: 3 | R22: 2 | S22: 1 | T22: timur | U22: {"keyword": true, "jenis_properti": true, "tipe_listing": false}
A23: 20251113-083353 | B23: 2025-11-13T08:33:53 | C23: test/test_vector_rval1.xlsx | D23: 10 | E23: 2 | F23: *Ruko Gandeng Kosong Daerah Krakatau | G23: https://metaproperty.co.id/listing/8406 | H23: 8406 | I23: 0.66666667 | J23: 0 | K23: 2800000000 | M23: 384 | N23: 128 | P23: 3 | Q23: kosong | R23: 2 | S23: 1 | T23: selatan | U23: {"keyword": true, "jenis_properti": true, "tipe_listing": false}
A24: 20251113-083353 | B24: 2025-11-13T08:33:53 | C24: test/test_vector_rval1.xlsx | D24: 10 | E24: 3 | F24: *RUKO/Townhouse Karantina _ Krakatau | G24: https://metaproperty.co.id/listing/938 | H24: 938 | I24: 0.66666667 | J24: 0 | K24: 475000000 | M24: 80 | N24: 48 | P24: 2 | R24: 2 | S24: 1 | T24: timur | U24: {"keyword": true, "jenis_properti": true, "tipe_listing": false}
A25: 20251113-083353 | B25: 2025-11-13T08:33:53 | C25: test/test_vector_rval1.xlsx | D25: 10 | E25: 4 | F25: *Dijual Ruko 2 Lantai di Daerah Krakatau | G25: https://metaproperty.co.id/listing/7441 | H25: 7441 | I25: 0.66666667 | J25: 0 | K25: 530000000 | L25: 3 | M25: 192 | N25: 96 | P25: 2 | R25: 2 | S25: 1 | U25: {"keyword": true, "jenis_properti": true, "tipe_listing": false}
A26: 20251113-083353 | B26: 2025-11-13T08:33:53 | C26: test/test_vector_rval1.xlsx | D26: 10 | E26: 5 | F26: *Dijual Ruko Siap Huni daerah Krakatau | G26: https://metaproperty.co.id/listing/5065 | H26: 5065 | I26: 0.66666667 | J26: 0 | K26: 1700000000 | L26: 3 | M26: 192 | N26: 100 | P26: 3 | R26: 2 | S26: 1 | T26: utara | U26: {"keyword": true, "jenis_properti": true, "tipe_listing": false}
A27: 20251113-083353 | B27: 2025-11-13T08:33:53 | C27: test/test_vector_rval1.xlsx | D27: 11 | E27: 1 | F27: Dijual tanah daerah Marelan | G27: https://metaproperty.co.id/listing/6912 | H27: 6912 | I27: 1 | J27: 1 | K27: 7000000000 | N27: 602 | R27: 3 | S27: 1 | U27: {"keyword": true, "jenis_properti": true, "tipe_listing": true}
A28: 20251113-083353 | B28: 2025-11-13T08:33:53 | C28: test/test_vector_rval1.xlsx | D28: 11 | E28: 2 | F28: Tanah + Rumah Marelan | G28: https://metaproperty.co.id/listing/257 | H28: 257 | I28: 1 | J28: 1 | K28: 4000000000 | N28: 3490 | R28: 3 | S28: 1 | T28: timur | U28: {"keyword": true, "jenis_properti": true, "tipe_listing": true}
A29: 20251113-083353 | B29: 2025-11-13T08:33:53 | C29: test/test_vector_rval1.xlsx | D29: 11 | E29: 3 | F29: Jual tanah beserta ex-cafe daerah Marelan | G29: https://metaproperty.co.id/listing/9916 | H29: 9916 | I29: 1 | J29: 1 | K29: 1700000000 | M29: 210 | N29: 756 | P29: 1 | R29: 3 | S29: 1 | T29: utara | U29: {"keyword": true, "jenis_properti": true, "tipe_listing": true}
A30: 20251113-083353 | B30: 2025-11-13T08:33:53 | C30: test/test_vector_rval1.xlsx | D30: 11 | E30: 4 | F30: Dijual tanah luas di daerah Marelan | G30: https://metaproperty.co.id/listing/9257 | H30: 9257 | I30: 0.66666667 | J30: 0 | K30: 450000000 | L30: 5 | M30: 242 | N30: 242 | P30: 1 | R30: 1 | S30: 1 | U30: {"keyword": true, "jenis_properti": false, "tipe_listing": true}
A31: 20251113-083353 | B31: 2025-11-13T08:33:53 | C31: test/test_vector_rval1.xlsx | D31: 11 | E31: 5 | F31: Rumah dijual di daerah Marelan | G31: https://metaproperty.co.id/listing/5117 | H31: 5117 | I31: 0.66666667 | J31: 0 | K31: 295000000 | L31: 2 | M31: 98 | N31: 116 | P31: 1 | R31: 1 | S31: 1 | U31: {"keyword": true, "jenis_properti": false, "tipe_listing": true}
A32: 20251113-083353 | B32: 2025-11-13T08:33:53 | C32: test/test_vector_rval1.xlsx | D32: 12 | E32: 1 | F32: *Gudang — Kab. Deli Serdang, Sumber Melati Diski | G32: https://metaproperty.co.id/listing/9845 | H32: 9845 | I32: 0.5 | J32: 0 | K32: 2200000000 | M32: 180 | N32: 1000 | R32: 5 | S32: 1 | T32: timur | U32: {"keyword": false, "jenis_properti": true}
A33: 20251113-083353 | B33: 2025-11-13T08:33:53 | C33: test/test_vector_rval1.xlsx | D33: 12 | E33: 2 | F33: *Dijual Gudang Cocok untuk Usaha — Kota Medan, Sekip | G33: https://metaproperty.co.id/listing/6936 | H33: 6936 | I33: 0.5 | J33: 0 | K33: 4350000000 | N33: 450 | R33: 5 | S33: 1 | T33: selatan | U33: {"keyword": false, "jenis_properti": true}
A34: 20251113-083353 | B34: 2025-11-13T08:33:53 | C34: test/test_vector_rval1.xlsx | D34: 12 | E34: 3 | F34: *Disewa Gudang Letda Sudjono — Kab. Deli Serdang, Tembung | G34: https://metaproperty.co.id/listing/192 | H34: 192 | I34: 0.5 | J34: 0 | K34: 248400000 | M34: 0 | N34: 1656 | P34: 1 | R34: 5 | S34: 2 | U34: {"keyword": false, "jenis_properti": true}
A35: 20251113-083353 | B35: 2025-11-13T08:33:53 | C35: test/test_vector_rval1.xlsx | D35: 12 | E35: 4 | F35: *Dijual Gudang Include Kantor — Kota Medan, Harjosari II | G35: https://metaproperty.co.id/listing/8007 | H35: 8007 | I35: 0.5 | J35: 0 | K35: 15000000000 | M35: 1311 | N35: 1770 | P35: 2 | R35: 5 | S35: 1 | U35: {"keyword": false, "jenis_properti": true}
A36: 20251113-083353 | B36: 2025-11-13T08:33:53 | C36: test/test_vector_rval1.xlsx | D36: 12 | E36: 5 | F36: *Dijual Gudang di Lintas Sumatera Indrapura — Kab. Batu Bara, Sipare-Pare | G36: https://metaproperty.co.id/listing/51 | H36: 51 | I36: 0.5 | J36: 0 | K36: 10000000000 | N36: 26500 | R36: 5 | S36: 1 | U36: {"keyword": false, "jenis_properti": true}
A37: 20251113-083353 | B37: 2025-11-13T08:33:53 | C37: test/test_vector_rval1.xlsx | D37: 13 | E37: 1 | F37: *Dijual full perabot daerah Ringroad — Kota Medan, Tanjung Sari | G37: https://metaproperty.co.id/listing/7980 | H37: 7980 | I37: 1 | J37: 1 | K37: 900000000 | L37: 3 | M37: 90 | N37: 90 | P37: 2 | R37: 1 | S37: 1 | T37: barat | U37: {"keyword": true, "harga_min": true, "harga_max": true, "kamar_tidur": true, "jenis_properti": true, "tipe_listing": true}
A38: 20251113-083353 | B38: 2025-11-13T08:33:53 | C38: test/test_vector_rval1.xlsx | D38: 13 | E38: 2 | F38: *Dijual Rumah Full Furnish di daerah ringroad — Kota Medan, Sunggal | G38: https://metaproperty.co.id/listing/9821 | H38: 9821 | I38: 0.83333333 | J38: 0 | K38: 1300000000 | L38: 3 | M38: 140 | N38: 162 | P38: 2 | R38: 1 | S38: 1 | U38: {"keyword": true, "harga_min": true, "harga_max": false, "kamar_tidur": true, "jenis_properti": true, "tipe_listing": true}
A39: 20251113-083353 | B39: 2025-11-13T08:33:53 | C39: test/test_vector_rval1.xlsx | D39: 13 | E39: 3 | F39: *Dijual Rumah Cantik Full Furnish Daerah Ringroad — Kota Medan, Sunggal | G39: https://metaproperty.co.id/listing/9724 | H39: 9724 | I39: 0.83333333 | J39: 0 | K39: 1300000000 | L39: 3 | M39: 144 | N39: 84 | P39: 2 | R39: 1 | S39: 1 | U39: {"keyword": true, "harga_min": true, "harga_max": false, "kamar_tidur": true, "jenis_properti": true, "tipe_listing": true}
A40: 20251113-083353 | B40: 2025-11-13T08:33:53 | C40: test/test_vector_rval1.xlsx | D40: 13 | E40: 4 | F40: *Rumah Komplek Daerah Ringroad — Kota Medan, Asam Kumbang | G40: https://metaproperty.co.id/listing/9614 | H40: 9614 | I40: 1 | J40: 1 | K40: 900000000 | L40: 3 | M40: 95 | N40: 94 | P40: 2 | R40: 1 | S40: 1 | U40: {"keyword": true, "harga_min": true, "harga_max": true, "kamar_tidur": true, "jenis_properti": true, "tipe_listing": true}
...

Sheet global_runs
A1: run_id | B1: run_ts | C1: xls_input | D1: threshold_T | E1: total_questions | F1: total_with_items | G1: total_no_result_conclusive | H1: macro_avg_pca | I1: macro_avg_precision | J1: macro_avg_recall | K1: macro_avg_f1 | L1: micro_accuracy | M1: avg_no_result_score | N1: TP | O1: FP | P1: FN | Q1: TN | R1: UNK | S1: cm_precision | T1: cm_recall | U1: cm_f1 | V1: cm_accuracy
A2: 20251113-083353 | B2: 2025-11-13T08:33:53 | C2: test/test_vector_rval1.xlsx | D2: 0.6 | E2: 30 | F2: 25 | G2: 5 | H2: 0.69436508 | I2: 1 | J2: 0.7532381 | K2: 0.83795289 | L2: 0.79874214 | M2: 0.4 | N2: 11 | O2: 3 | P2: 14 | Q2: 2 | R2: 0 | S2: 0.78571429 | T2: 0.44 | U2: 0.56410256 | V2: 0.43333333
E3: =COUNT(per_question!D2:D31) -> 30 | F3: =COUNTIF(per_question!$E$2:$E$31,"TRUE") -> 25 | G3: =COUNTIF(per_question!$E$2:$E$31,"FALSE") -> 5 | H3: =AVERAGE(per_item!I2:I108) -> 0.82478861 | N3: =COUNTIF(per_question!$Q$2:$Q$31,"TP") -> 14 | O3: =COUNTIF(per_question!$Q$2:$Q$31,"FP") -> 3 | P3: =COUNTIF(per_question!$Q$2:$Q$31,"FN") -> 11 | Q3: =COUNTIF(per_question!$Q$2:$Q$31,"TN") -> 2 | R3: =COUNTIF(per_question!$Q$2:$Q$31,"UNK") -> 0 | S3: =N3/(N3+O3) -> 0.82352941 | T3: =N3/(N3+P3) -> 0.56 | U3: =2*S3*T3/(S3+T3) -> 0.66666667 | V3: =(N3+Q3)/SUM(N3:Q3) -> 0.53333333
